El manejo de errores es una parte crucial del trabajo con promesas en JavaScript. Debido a que las promesas pueden resolverse satisfactoriamente o ser rechazadas, es importante saber cómo capturar y manejar estos rechazos adecuadamente.

#### Uso de `.catch()`

La forma más común de manejar errores en promesas es utilizando el método `.catch()`. Este método se encadena después de `.then()` y se ejecuta si la promesa es rechazada en algún punto de la cadena de promesas.

**Ejemplo Básico de Uso de `.catch()`:**

javascript

Copiar código

`const promesa = new Promise((resolve, reject) => {     const exito = false;     if (exito) {         resolve("Operación exitosa");     } else {         reject("Operación fallida");     } });  promesa     .then(resultado => console.log(resultado))     .catch(error => console.error(error));  // Se ejecuta si la promesa es rechazada`

#### Encadenamiento de Promesas y Captura de Errores

Los errores pueden propagarse a través de una cadena de promesas hasta que son capturados por un `.catch()`. Si no se captura el error, este se propagará hasta que encuentre un handler de error adecuado, y si no encuentra ninguno, se mostrará como un error no capturado.

**Ejemplo de Encadenamiento:**

javascript

Copiar código

`function fallar() {     return new Promise((resolve, reject) => {         reject("Error intencionado");     }); }  fallar()     .then(() => console.log("Esto no se ejecutará"))     .catch(error => console.error("Capturado en el catch:", error));`

#### Manejo de Errores con `async` y `await`

Cuando usas `async` y `await`, el manejo de errores se puede hacer de una manera más tradicional utilizando bloques `try...catch`.

**Ejemplo de `async` y `await` con Manejo de Errores:**

javascript

Copiar código

`async function operacionAsincrona() {     try {         const resultado = await new Promise((resolve, reject) => {             reject("Algo salió mal");         });         console.log(resultado);     } catch (error) {         console.error("Error manejado:", error);     } }  operacionAsincrona();`

En este ejemplo, cualquier error que ocurra dentro de la promesa o en cualquier operación `await` dentro del bloque `try` será capturado por el `catch` correspondiente.

#### `Promise.all()` y Manejo de Errores

Cuando usas `Promise.all()`, si una de las promesas en el array es rechazada, `Promise.all()` se rechaza inmediatamente con ese error, y las demás promesas no resueltas se ignoran.

**Ejemplo de `Promise.all()` con Manejo de Errores:**

javascript

Copiar código

`const promesa1 = Promise.resolve("Primera promesa"); const promesa2 = Promise.reject("Error en segunda promesa");  Promise.all([promesa1, promesa2])     .then(resultados => console.log(resultados))     .catch(error => console.error("Error en Promise.all:", error));`


---
![[Pasted image 20240516145814.png]]![[Pasted image 20240516145859.png]]
